Traceback (most recent call last):
  File "C:\Users\popko\PycharmProjects\M13FirstBot\.venv\lib\site-packages\aiogram\dispatcher\dispatcher.py", line 415, in _process_polling_updates
    for responses in itertools.chain.from_iterable(await self.process_updates(updates, fast)):
  File "C:\Users\popko\PycharmProjects\M13FirstBot\.venv\lib\site-packages\aiogram\dispatcher\dispatcher.py", line 235, in process_updates
    return await asyncio.gather(*tasks)
  File "C:\Users\popko\PycharmProjects\M13FirstBot\.venv\lib\site-packages\aiogram\dispatcher\handler.py", line 117, in notify
    response = await handler_obj.handler(*args, **partial_data)
  File "C:\Users\popko\PycharmProjects\M13FirstBot\.venv\lib\site-packages\aiogram\dispatcher\dispatcher.py", line 256, in process_update
    return await self.message_handlers.notify(update.message)
  File "C:\Users\popko\PycharmProjects\M13FirstBot\.venv\lib\site-packages\aiogram\dispatcher\handler.py", line 117, in notify
    response = await handler_obj.handler(*args, **partial_data)
  File "C:\Users\popko\PycharmProjects\M14_4\module_14_5.py", line 134, in set_username
    new_user = crud_function.is_included(message.text)
  File "C:\Users\popko\PycharmProjects\M14_4\crud_function.py", line 67, in is_included
    connection.sqlite3.connect('Users.db')
AttributeError: 'sqlite3.Connection' object has no attribute 'sqlite3'